2024-11-14 11:51:49,694 - ERROR: Invalid transport for session 2nK7kQ0AupF0sYnCAAAA (further occurrences of this error will be logged with level INFO)
2024-11-14 11:51:54,320 - DEBUG: 14 BLE-Devices found
2024-11-14 11:51:58,778 - ERROR: Exception on request GET /driver/
Traceback (most recent call last):
  File "C:\Users\mariok\.virtualenvs\IAV_Distortion-8tpuzdpM\Lib\site-packages\quart\app.py", line 1403, in handle_request
    return await self.full_dispatch_request(request_context)
           ^^^^^^^^^^^^^^^^^^^^^^^^^^^^^^^^^^^^^^^^^^^^^^^^^
  File "C:\Users\mariok\.virtualenvs\IAV_Distortion-8tpuzdpM\Lib\site-packages\quart\app.py", line 1441, in full_dispatch_request
    result = await self.handle_user_exception(error)
             ^^^^^^^^^^^^^^^^^^^^^^^^^^^^^^^^^^^^^^^
  File "C:\Users\mariok\.virtualenvs\IAV_Distortion-8tpuzdpM\Lib\site-packages\quart\app.py", line 1029, in handle_user_exception
    raise error
  File "C:\Users\mariok\.virtualenvs\IAV_Distortion-8tpuzdpM\Lib\site-packages\quart\app.py", line 1439, in full_dispatch_request
    result = await self.dispatch_request(request_context)
             ^^^^^^^^^^^^^^^^^^^^^^^^^^^^^^^^^^^^^^^^^^^^
  File "C:\Users\mariok\.virtualenvs\IAV_Distortion-8tpuzdpM\Lib\site-packages\quart\app.py", line 1535, in dispatch_request
    return await self.ensure_async(handler)(**request_.view_args)  # type: ignore
           ^^^^^^^^^^^^^^^^^^^^^^^^^^^^^^^^^^^^^^^^^^^^^^^^^^^^^^
  File "C:\Users\mariok\IdeaProjects\IAV Distortion\IAV_Distortion\src\UserInterface\DriverUI.py", line 77, in home_driver
    player_exists, picture, vehicle_information = self._prepare_html_data(player)
                                                  ^^^^^^^^^^^^^^^^^^^^^^^^^^^^^^^
  File "C:\Users\mariok\IdeaProjects\IAV Distortion\IAV_Distortion\src\UserInterface\DriverUI.py", line 357, in _prepare_html_data
    self.environment_mng.put_player_on_next_free_spot(player)
  File "C:\Users\mariok\IdeaProjects\IAV Distortion\IAV_Distortion\src\EnvironmentManagement\EnvironmentManager.py", line 277, in put_player_on_next_free_spot
    result = self._assign_players_to_vehicles()
             ^^^^^^^^^^^^^^^^^^^^^^^^^^^^^^^^^^
  File "C:\Users\mariok\IdeaProjects\IAV Distortion\IAV_Distortion\src\EnvironmentManagement\EnvironmentManager.py", line 302, in _assign_players_to_vehicles
    active_bot = self.get_bot_by_vehicle_id(vehicle.get_vehicle_id())
                 ^^^^^^^^^^^^^^^^^^^^^^^^^^^^^^^^^^^^^^^^^^^^^^^^^^^^
  File "C:\Users\mariok\IdeaProjects\IAV Distortion\IAV_Distortion\src\EnvironmentManagement\EnvironmentManager.py", line 779, in get_bot_by_vehicle_id
    for b in self._active_bots:
             ^^^^^^^^^^^^^^^^^
AttributeError: 'EnvironmentManager' object has no attribute '_active_bots'
2024-11-14 11:52:01,344 - INFO: Car Virtual Vehicle 1 now has the effect VehicleEffectIdentification.HACKING_PROTECTION
2024-11-14 11:52:01,345 - INFO: Car Virtual Vehicle 1 now has the effect VehicleEffectIdentification.CLEAN_HACKED_EFFECTS
2024-11-14 11:52:09,432 - INFO: Removing player with UUID 91bbb946-a49c-43ce-a0fd-2a71ee20447b from vehicle
2024-11-14 11:52:09,615 - ERROR: Task exception was never retrieved
future: <Task finished name='Task-2141' coro=<DriverUI.__send_proximity_vehicle() done, defined at C:\Users\mariok\IdeaProjects\IAV Distortion\IAV_Distortion\src\UserInterface\DriverUI.py:255> exception=AttributeError("'NoneType' object has no attribute 'vehicle_in_proximity'")>
Traceback (most recent call last):
  File "C:\Users\mariok\IdeaProjects\IAV Distortion\IAV_Distortion\src\UserInterface\DriverUI.py", line 270, in __send_proximity_vehicle
    if previous_vehicle_in_proximity != vehicle.vehicle_in_proximity:
                                        ^^^^^^^^^^^^^^^^^^^^^^^^^^^^
AttributeError: 'NoneType' object has no attribute 'vehicle_in_proximity'
2024-11-14 11:52:26,716 - INFO: -------------------------
2024-11-14 11:52:26,717 - INFO:  STARTING IAV-Distortion 
2024-11-14 11:52:26,717 - INFO: -------------------------
2024-11-14 11:52:26,728 - INFO: Auto discovery service for Anki cars activated.
2024-11-14 11:52:26,801 - INFO: Running on http://0.0.0.0:5000 (CTRL + C to quit)
2024-11-14 11:52:26,925 - ERROR: Invalid session PsmyEx8k85Lr84YFAAAC (further occurrences of this error will be logged with level INFO)
2024-11-14 11:52:27,236 - ERROR: Invalid transport for session qgYjLMgci8HkRgelAAAA (further occurrences of this error will be logged with level INFO)
2024-11-14 11:52:31,822 - DEBUG: 13 BLE-Devices found
2024-11-14 11:52:31,908 - INFO: Car Virtual Vehicle 1 now has the effect VehicleEffectIdentification.HACKING_PROTECTION
2024-11-14 11:52:31,909 - INFO: Car Virtual Vehicle 1 now has the effect VehicleEffectIdentification.CLEAN_HACKED_EFFECTS
2024-11-14 11:52:33,915 - ERROR: Exception on request GET /driver/
Traceback (most recent call last):
  File "C:\Users\mariok\.virtualenvs\IAV_Distortion-8tpuzdpM\Lib\site-packages\quart\app.py", line 1403, in handle_request
    return await self.full_dispatch_request(request_context)
           ^^^^^^^^^^^^^^^^^^^^^^^^^^^^^^^^^^^^^^^^^^^^^^^^^
  File "C:\Users\mariok\.virtualenvs\IAV_Distortion-8tpuzdpM\Lib\site-packages\quart\app.py", line 1441, in full_dispatch_request
    result = await self.handle_user_exception(error)
             ^^^^^^^^^^^^^^^^^^^^^^^^^^^^^^^^^^^^^^^
  File "C:\Users\mariok\.virtualenvs\IAV_Distortion-8tpuzdpM\Lib\site-packages\quart\app.py", line 1029, in handle_user_exception
    raise error
  File "C:\Users\mariok\.virtualenvs\IAV_Distortion-8tpuzdpM\Lib\site-packages\quart\app.py", line 1439, in full_dispatch_request
    result = await self.dispatch_request(request_context)
             ^^^^^^^^^^^^^^^^^^^^^^^^^^^^^^^^^^^^^^^^^^^^
  File "C:\Users\mariok\.virtualenvs\IAV_Distortion-8tpuzdpM\Lib\site-packages\quart\app.py", line 1535, in dispatch_request
    return await self.ensure_async(handler)(**request_.view_args)  # type: ignore
           ^^^^^^^^^^^^^^^^^^^^^^^^^^^^^^^^^^^^^^^^^^^^^^^^^^^^^^
  File "C:\Users\mariok\IdeaProjects\IAV Distortion\IAV_Distortion\src\UserInterface\DriverUI.py", line 77, in home_driver
    player_exists, picture, vehicle_information = self._prepare_html_data(player)
                                                  ^^^^^^^^^^^^^^^^^^^^^^^^^^^^^^^
  File "C:\Users\mariok\IdeaProjects\IAV Distortion\IAV_Distortion\src\UserInterface\DriverUI.py", line 357, in _prepare_html_data
    self.environment_mng.put_player_on_next_free_spot(player)
  File "C:\Users\mariok\IdeaProjects\IAV Distortion\IAV_Distortion\src\EnvironmentManagement\EnvironmentManager.py", line 277, in put_player_on_next_free_spot
    result = self._assign_players_to_vehicles()
             ^^^^^^^^^^^^^^^^^^^^^^^^^^^^^^^^^^
  File "C:\Users\mariok\IdeaProjects\IAV Distortion\IAV_Distortion\src\EnvironmentManagement\EnvironmentManager.py", line 302, in _assign_players_to_vehicles
    active_bot = self.get_bot_by_vehicle_id(vehicle.get_vehicle_id())
                 ^^^^^^^^^^^^^^^^^^^^^^^^^^^^^^^^^^^^^^^^^^^^^^^^^^^^
  File "C:\Users\mariok\IdeaProjects\IAV Distortion\IAV_Distortion\src\EnvironmentManagement\EnvironmentManager.py", line 779, in get_bot_by_vehicle_id
    for b in self._active_bots:
             ^^^^^^^^^^^^^^^^^
AttributeError: 'EnvironmentManager' object has no attribute '_active_bots'
2024-11-14 11:53:19,273 - INFO: -------------------------
2024-11-14 11:53:19,273 - INFO:  STARTING IAV-Distortion 
2024-11-14 11:53:19,273 - INFO: -------------------------
2024-11-14 11:53:19,283 - INFO: Auto discovery service for Anki cars activated.
2024-11-14 11:53:19,350 - INFO: Running on http://0.0.0.0:5000 (CTRL + C to quit)
2024-11-14 11:53:19,625 - ERROR: Invalid session Ycv2VLxk7Na55KtFAAAG (further occurrences of this error will be logged with level INFO)
2024-11-14 11:53:19,937 - ERROR: Invalid transport for session eWYUmy0ggeig6OAnAAAA (further occurrences of this error will be logged with level INFO)
2024-11-14 11:53:24,364 - DEBUG: 11 BLE-Devices found
2024-11-14 11:53:25,068 - ERROR: Task exception was never retrieved
future: <Task finished name='Task-301' coro=<AsyncServer._handle_event_internal() done, defined at C:\Users\mariok\.virtualenvs\IAV_Distortion-8tpuzdpM\Lib\site-packages\socketio\async_server.py:608> exception=AttributeError("'EnvironmentManager' object has no attribute '_aktive_bots'")>
Traceback (most recent call last):
  File "C:\Users\mariok\.virtualenvs\IAV_Distortion-8tpuzdpM\Lib\site-packages\socketio\async_server.py", line 610, in _handle_event_internal
    r = await server._trigger_event(data[0], namespace, sid, *data[1:])
        ^^^^^^^^^^^^^^^^^^^^^^^^^^^^^^^^^^^^^^^^^^^^^^^^^^^^^^^^^^^^^^^
  File "C:\Users\mariok\.virtualenvs\IAV_Distortion-8tpuzdpM\Lib\site-packages\socketio\async_server.py", line 637, in _trigger_event
    ret = await handler(*args)
          ^^^^^^^^^^^^^^^^^^^^
  File "C:\Users\mariok\IdeaProjects\IAV Distortion\IAV_Distortion\src\UserInterface\StaffUI.py", line 245, in handle_add_virtual_vehicle
    name = environment_mng.add_virtual_vehicle()
           ^^^^^^^^^^^^^^^^^^^^^^^^^^^^^^^^^^^^^
  File "C:\Users\mariok\IdeaProjects\IAV Distortion\IAV_Distortion\src\EnvironmentManagement\EnvironmentManager.py", line 683, in add_virtual_vehicle
    self._aktive_bots.append(new_bot)
    ^^^^^^^^^^^^^^^^^
AttributeError: 'EnvironmentManager' object has no attribute '_aktive_bots'
2024-11-14 11:53:43,582 - INFO: Car Virtual Vehicle 1 now has the effect VehicleEffectIdentification.HACKING_PROTECTION
2024-11-14 11:53:43,583 - INFO: Car Virtual Vehicle 1 now has the effect VehicleEffectIdentification.CLEAN_HACKED_EFFECTS
2024-11-14 11:53:55,141 - INFO: -------------------------
2024-11-14 11:53:55,142 - INFO:  STARTING IAV-Distortion 
2024-11-14 11:53:55,142 - INFO: -------------------------
2024-11-14 11:53:55,155 - INFO: Auto discovery service for Anki cars activated.
2024-11-14 11:53:55,219 - INFO: Running on http://0.0.0.0:5000 (CTRL + C to quit)
2024-11-14 11:53:55,597 - ERROR: Invalid transport for session 3wlOS6i0PgZzqszAAAAA (further occurrences of this error will be logged with level INFO)
2024-11-14 11:54:00,227 - DEBUG: 12 BLE-Devices found
2024-11-14 11:54:01,648 - ERROR: Task exception was never retrieved
future: <Task finished name='Task-133' coro=<AsyncServer._handle_event_internal() done, defined at C:\Users\mariok\.virtualenvs\IAV_Distortion-8tpuzdpM\Lib\site-packages\socketio\async_server.py:608> exception=AttributeError("'EnvironmentManager' object has no attribute '_aktive_bots'")>
Traceback (most recent call last):
  File "C:\Users\mariok\.virtualenvs\IAV_Distortion-8tpuzdpM\Lib\site-packages\socketio\async_server.py", line 610, in _handle_event_internal
    r = await server._trigger_event(data[0], namespace, sid, *data[1:])
        ^^^^^^^^^^^^^^^^^^^^^^^^^^^^^^^^^^^^^^^^^^^^^^^^^^^^^^^^^^^^^^^
  File "C:\Users\mariok\.virtualenvs\IAV_Distortion-8tpuzdpM\Lib\site-packages\socketio\async_server.py", line 637, in _trigger_event
    ret = await handler(*args)
          ^^^^^^^^^^^^^^^^^^^^
  File "C:\Users\mariok\IdeaProjects\IAV Distortion\IAV_Distortion\src\UserInterface\StaffUI.py", line 245, in handle_add_virtual_vehicle
    name = environment_mng.add_virtual_vehicle()
           ^^^^^^^^^^^^^^^^^^^^^^^^^^^^^^^^^^^^^
  File "C:\Users\mariok\IdeaProjects\IAV Distortion\IAV_Distortion\src\EnvironmentManagement\EnvironmentManager.py", line 683, in add_virtual_vehicle
    self._aktive_bots.append(new_bot)
    ^^^^^^^^^^^^^^^^^
AttributeError: 'EnvironmentManager' object has no attribute '_aktive_bots'
2024-11-14 11:54:15,548 - INFO: -------------------------
2024-11-14 11:54:15,548 - INFO:  STARTING IAV-Distortion 
2024-11-14 11:54:15,549 - INFO: -------------------------
2024-11-14 11:54:15,558 - INFO: Auto discovery service for Anki cars activated.
2024-11-14 11:54:15,626 - INFO: Running on http://0.0.0.0:5000 (CTRL + C to quit)
2024-11-14 11:54:16,007 - ERROR: Invalid transport for session cLGP97HCEU3gnzwcAAAA (further occurrences of this error will be logged with level INFO)
2024-11-14 11:54:20,631 - DEBUG: 12 BLE-Devices found
2024-11-14 11:54:22,669 - ERROR: Exception on request GET /driver/
Traceback (most recent call last):
  File "C:\Users\mariok\.virtualenvs\IAV_Distortion-8tpuzdpM\Lib\site-packages\quart\app.py", line 1403, in handle_request
    return await self.full_dispatch_request(request_context)
           ^^^^^^^^^^^^^^^^^^^^^^^^^^^^^^^^^^^^^^^^^^^^^^^^^
  File "C:\Users\mariok\.virtualenvs\IAV_Distortion-8tpuzdpM\Lib\site-packages\quart\app.py", line 1441, in full_dispatch_request
    result = await self.handle_user_exception(error)
             ^^^^^^^^^^^^^^^^^^^^^^^^^^^^^^^^^^^^^^^
  File "C:\Users\mariok\.virtualenvs\IAV_Distortion-8tpuzdpM\Lib\site-packages\quart\app.py", line 1029, in handle_user_exception
    raise error
  File "C:\Users\mariok\.virtualenvs\IAV_Distortion-8tpuzdpM\Lib\site-packages\quart\app.py", line 1439, in full_dispatch_request
    result = await self.dispatch_request(request_context)
             ^^^^^^^^^^^^^^^^^^^^^^^^^^^^^^^^^^^^^^^^^^^^
  File "C:\Users\mariok\.virtualenvs\IAV_Distortion-8tpuzdpM\Lib\site-packages\quart\app.py", line 1535, in dispatch_request
    return await self.ensure_async(handler)(**request_.view_args)  # type: ignore
           ^^^^^^^^^^^^^^^^^^^^^^^^^^^^^^^^^^^^^^^^^^^^^^^^^^^^^^
  File "C:\Users\mariok\IdeaProjects\IAV Distortion\IAV_Distortion\src\UserInterface\DriverUI.py", line 77, in home_driver
    player_exists, picture, vehicle_information = self._prepare_html_data(player)
                                                  ^^^^^^^^^^^^^^^^^^^^^^^^^^^^^^^
  File "C:\Users\mariok\IdeaProjects\IAV Distortion\IAV_Distortion\src\UserInterface\DriverUI.py", line 357, in _prepare_html_data
    self.environment_mng.put_player_on_next_free_spot(player)
  File "C:\Users\mariok\IdeaProjects\IAV Distortion\IAV_Distortion\src\EnvironmentManagement\EnvironmentManager.py", line 277, in put_player_on_next_free_spot
    result = self._assign_players_to_vehicles()
             ^^^^^^^^^^^^^^^^^^^^^^^^^^^^^^^^^^
  File "C:\Users\mariok\IdeaProjects\IAV Distortion\IAV_Distortion\src\EnvironmentManagement\EnvironmentManager.py", line 302, in _assign_players_to_vehicles
    active_bot = self.get_bot_by_vehicle_id(vehicle.get_vehicle_id())
                 ^^^^^^^^^^^^^^^^^^^^^^^^^^^^^^^^^^^^^^^^^^^^^^^^^^^^
  File "C:\Users\mariok\IdeaProjects\IAV Distortion\IAV_Distortion\src\EnvironmentManagement\EnvironmentManager.py", line 780, in get_bot_by_vehicle_id
    if b.get_vehicle_id() == vehicle_id:
       ^^^^^^^^^^^^^^^^
AttributeError: 'Bot' object has no attribute 'get_vehicle_id'
2024-11-14 11:54:52,762 - INFO: Player 91bbb946-a49c-43ce-a0fd-2a71ee20447b timed out. Removing player from the game...
2024-11-14 11:54:57,756 - INFO: Removing player with UUID 91bbb946-a49c-43ce-a0fd-2a71ee20447b from vehicle
2024-11-14 11:54:57,932 - ERROR: Task exception was never retrieved
future: <Task finished name='Task-1270' coro=<DriverUI.__send_proximity_vehicle() done, defined at C:\Users\mariok\IdeaProjects\IAV Distortion\IAV_Distortion\src\UserInterface\DriverUI.py:255> exception=AttributeError("'NoneType' object has no attribute 'vehicle_in_proximity'")>
Traceback (most recent call last):
  File "C:\Users\mariok\IdeaProjects\IAV Distortion\IAV_Distortion\src\UserInterface\DriverUI.py", line 270, in __send_proximity_vehicle
    if previous_vehicle_in_proximity != vehicle.vehicle_in_proximity:
                                        ^^^^^^^^^^^^^^^^^^^^^^^^^^^^
AttributeError: 'NoneType' object has no attribute 'vehicle_in_proximity'
2024-11-14 11:55:08,004 - INFO: Car Virtual Vehicle 1 now has the effect VehicleEffectIdentification.HACKING_PROTECTION
2024-11-14 11:55:08,005 - INFO: Car Virtual Vehicle 1 now has the effect VehicleEffectIdentification.CLEAN_HACKED_EFFECTS
2024-11-14 11:55:25,271 - INFO: -------------------------
2024-11-14 11:55:25,272 - INFO:  STARTING IAV-Distortion 
2024-11-14 11:55:25,273 - INFO: -------------------------
2024-11-14 11:55:25,283 - INFO: Auto discovery service for Anki cars activated.
2024-11-14 11:55:25,354 - INFO: Running on http://0.0.0.0:5000 (CTRL + C to quit)
2024-11-14 11:55:25,514 - ERROR: Invalid session cLGP97HCEU3gnzwcAAAA (further occurrences of this error will be logged with level INFO)
2024-11-14 11:55:26,774 - ERROR: Invalid transport for session 28IXBvfQNJFRckrtAAAA (further occurrences of this error will be logged with level INFO)
2024-11-14 11:55:29,582 - INFO: Car Virtual Vehicle 1 now has the effect VehicleEffectIdentification.HACKING_PROTECTION
2024-11-14 11:55:29,583 - INFO: Car Virtual Vehicle 1 now has the effect VehicleEffectIdentification.CLEAN_HACKED_EFFECTS
2024-11-14 11:55:30,366 - DEBUG: 9 BLE-Devices found
2024-11-14 11:55:43,028 - INFO: Removing player with UUID 91bbb946-a49c-43ce-a0fd-2a71ee20447b from vehicle
2024-11-14 11:55:43,174 - ERROR: Task exception was never retrieved
future: <Task finished name='Task-703' coro=<DriverUI.__send_proximity_vehicle() done, defined at C:\Users\mariok\IdeaProjects\IAV Distortion\IAV_Distortion\src\UserInterface\DriverUI.py:255> exception=AttributeError("'NoneType' object has no attribute 'vehicle_in_proximity'")>
Traceback (most recent call last):
  File "C:\Users\mariok\IdeaProjects\IAV Distortion\IAV_Distortion\src\UserInterface\DriverUI.py", line 270, in __send_proximity_vehicle
    if previous_vehicle_in_proximity != vehicle.vehicle_in_proximity:
                                        ^^^^^^^^^^^^^^^^^^^^^^^^^^^^
AttributeError: 'NoneType' object has no attribute 'vehicle_in_proximity'
2024-11-14 11:55:49,664 - INFO: -------------------------
2024-11-14 11:55:49,664 - INFO:  STARTING IAV-Distortion 
2024-11-14 11:55:49,666 - INFO: -------------------------
2024-11-14 11:55:49,675 - INFO: Auto discovery service for Anki cars activated.
2024-11-14 11:55:49,746 - INFO: Running on http://0.0.0.0:5000 (CTRL + C to quit)
2024-11-14 11:55:50,101 - ERROR: Invalid session l9NJL9WgjpBmAQcvAAAE (further occurrences of this error will be logged with level INFO)
2024-11-14 11:55:50,692 - ERROR: Invalid transport for session oipp6c2zBohRlheJAAAA (further occurrences of this error will be logged with level INFO)
2024-11-14 11:55:54,755 - DEBUG: 12 BLE-Devices found
2024-11-14 11:55:57,473 - ERROR: Exception in callback _ProactorBasePipeTransport._call_connection_lost(None)
handle: <Handle _ProactorBasePipeTransport._call_connection_lost(None)>
Traceback (most recent call last):
  File "C:\Users\mariok\AppData\Local\Programs\Python\Python311\Lib\asyncio\events.py", line 80, in _run
    self._context.run(self._callback, *self._args)
  File "C:\Users\mariok\AppData\Local\Programs\Python\Python311\Lib\asyncio\proactor_events.py", line 162, in _call_connection_lost
    self._sock.shutdown(socket.SHUT_RDWR)
ConnectionResetError: [WinError 10054] Eine vorhandene Verbindung wurde vom Remotehost geschlossen
2024-11-14 11:56:02,678 - INFO: Car Virtual Vehicle 3 now has the effect VehicleEffectIdentification.HACKING_PROTECTION
2024-11-14 11:56:02,678 - INFO: Car Virtual Vehicle 3 now has the effect VehicleEffectIdentification.CLEAN_HACKED_EFFECTS
2024-11-14 11:56:52,072 - INFO: Car Virtual Vehicle 1 now has the effect VehicleEffectIdentification.HACKING_PROTECTION
2024-11-14 11:56:52,073 - INFO: Car Virtual Vehicle 1 now has the effect VehicleEffectIdentification.CLEAN_HACKED_EFFECTS
2024-11-14 11:56:59,763 - DEBUG: 12 BLE-Devices found
2024-11-14 11:57:03,393 - INFO: Car Virtual Vehicle 3 doesn't have the effect VehicleEffectIdentification.HACKING_PROTECTION anymore
2024-11-14 12:29:42,422 - INFO: -------------------------
